2019-05-17 12:18:15,519 ERROR: Exception on /getchatbot [GET] [in c:\users\celia\microblog\venv\lib\site-packages\flask\app.py:1761]
Traceback (most recent call last):
  File "c:\users\celia\microblog\venv\lib\site-packages\flask\app.py", line 2292, in wsgi_app
    response = self.full_dispatch_request()
  File "c:\users\celia\microblog\venv\lib\site-packages\flask\app.py", line 1815, in full_dispatch_request
    rv = self.handle_user_exception(e)
  File "c:\users\celia\microblog\venv\lib\site-packages\flask\app.py", line 1718, in handle_user_exception
    reraise(exc_type, exc_value, tb)
  File "c:\users\celia\microblog\venv\lib\site-packages\flask\_compat.py", line 35, in reraise
    raise value
  File "c:\users\celia\microblog\venv\lib\site-packages\flask\app.py", line 1813, in full_dispatch_request
    rv = self.dispatch_request()
  File "c:\users\celia\microblog\venv\lib\site-packages\flask\app.py", line 1799, in dispatch_request
    return self.view_functions[rule.endpoint](**req.view_args)
  File "C:\Users\celia\PIAChatbot\app\main\routes.py", line 167, in get_bot_response
    NLU(int(current_user.id),str(userText)).runNLU()
  File "C:\Users\celia\PIAChatbot\app\main\natural_langage.py", line 575, in runNLU
    tempIntent = self.GetIntent(myInput,sujet,verbe)
  File "C:\Users\celia\PIAChatbot\app\main\natural_langage.py", line 450, in GetIntent
    if (token.text.capitalize(), 'male') in names and (prenomObtenu == "faux"):
TypeError: argument of type 'LazyCorpusLoader' is not iterable
2019-05-17 12:21:13,188 INFO: PIA Chatbot startup [in C:\Users\celia\PIAChatbot\app\__init__.py:73]
2019-05-17 12:21:37,240 ERROR: Exception on /getchatbot [GET] [in c:\users\celia\microblog\venv\lib\site-packages\flask\app.py:1761]
Traceback (most recent call last):
  File "c:\users\celia\microblog\venv\lib\site-packages\flask\app.py", line 2292, in wsgi_app
    response = self.full_dispatch_request()
  File "c:\users\celia\microblog\venv\lib\site-packages\flask\app.py", line 1815, in full_dispatch_request
    rv = self.handle_user_exception(e)
  File "c:\users\celia\microblog\venv\lib\site-packages\flask\app.py", line 1718, in handle_user_exception
    reraise(exc_type, exc_value, tb)
  File "c:\users\celia\microblog\venv\lib\site-packages\flask\_compat.py", line 35, in reraise
    raise value
  File "c:\users\celia\microblog\venv\lib\site-packages\flask\app.py", line 1813, in full_dispatch_request
    rv = self.dispatch_request()
  File "c:\users\celia\microblog\venv\lib\site-packages\flask\app.py", line 1799, in dispatch_request
    return self.view_functions[rule.endpoint](**req.view_args)
  File "C:\Users\celia\PIAChatbot\app\main\routes.py", line 167, in get_bot_response
    NLU(int(current_user.id),str(userText)).runNLU()
  File "C:\Users\celia\PIAChatbot\app\main\natural_langage.py", line 575, in runNLU
    tempIntent = self.GetIntent(myInput,sujet,verbe)
  File "C:\Users\celia\PIAChatbot\app\main\natural_langage.py", line 450, in GetIntent
    if (token.text.capitalize(), 'male') in names and (prenomObtenu == "faux"):
TypeError: argument of type 'LazyCorpusLoader' is not iterable
