2019-05-17 21:16:23,318 ERROR: Exception on /getchatbot [GET] [in c:\users\celia\microblog\venv\lib\site-packages\flask\app.py:1761]
Traceback (most recent call last):
  File "c:\users\celia\microblog\venv\lib\site-packages\flask\app.py", line 2292, in wsgi_app
    response = self.full_dispatch_request()
  File "c:\users\celia\microblog\venv\lib\site-packages\flask\app.py", line 1815, in full_dispatch_request
    rv = self.handle_user_exception(e)
  File "c:\users\celia\microblog\venv\lib\site-packages\flask\app.py", line 1718, in handle_user_exception
    reraise(exc_type, exc_value, tb)
  File "c:\users\celia\microblog\venv\lib\site-packages\flask\_compat.py", line 35, in reraise
    raise value
  File "c:\users\celia\microblog\venv\lib\site-packages\flask\app.py", line 1813, in full_dispatch_request
    rv = self.dispatch_request()
  File "c:\users\celia\microblog\venv\lib\site-packages\flask\app.py", line 1799, in dispatch_request
    return self.view_functions[rule.endpoint](**req.view_args)
  File "C:\Users\celia\PIAChatbot\app\main\routes.py", line 202, in get_bot_response
    NLU(cnx,cursor,userID,str(userText)).runNLU()
  File "C:\Users\celia\PIAChatbot\app\main\natural_langage.py", line 569, in runNLU
    tempIntent = self.GetIntent(myInput,sujet,verbe)
  File "C:\Users\celia\PIAChatbot\app\main\natural_langage.py", line 419, in GetIntent
    listeProfession = self.getJobList()
  File "C:\Users\celia\PIAChatbot\app\main\natural_langage.py", line 202, in getJobList
    self.cursor.execute("SELECT met_metier FROM Metiers;")
  File "c:\users\celia\microblog\venv\lib\site-packages\mysql\connector\cursor_cext.py", line 233, in execute
    raise errors.ProgrammingError("Cursor is not connected")
mysql.connector.errors.ProgrammingError: Cursor is not connected
2019-05-17 21:23:16,780 INFO: PIA Chatbot startup [in C:\Users\celia\PIAChatbot\app\__init__.py:73]
2019-05-17 21:23:57,714 ERROR: Exception on /getchatbot [GET] [in c:\users\celia\microblog\venv\lib\site-packages\flask\app.py:1761]
Traceback (most recent call last):
  File "c:\users\celia\microblog\venv\lib\site-packages\flask\app.py", line 2292, in wsgi_app
    response = self.full_dispatch_request()
  File "c:\users\celia\microblog\venv\lib\site-packages\flask\app.py", line 1815, in full_dispatch_request
    rv = self.handle_user_exception(e)
  File "c:\users\celia\microblog\venv\lib\site-packages\flask\app.py", line 1718, in handle_user_exception
    reraise(exc_type, exc_value, tb)
  File "c:\users\celia\microblog\venv\lib\site-packages\flask\_compat.py", line 35, in reraise
    raise value
  File "c:\users\celia\microblog\venv\lib\site-packages\flask\app.py", line 1813, in full_dispatch_request
    rv = self.dispatch_request()
  File "c:\users\celia\microblog\venv\lib\site-packages\flask\app.py", line 1799, in dispatch_request
    return self.view_functions[rule.endpoint](**req.view_args)
  File "C:\Users\celia\PIAChatbot\app\main\routes.py", line 202, in get_bot_response
    NLU(cnx,cursor,userID,str(userText)).runNLU()
  File "C:\Users\celia\PIAChatbot\app\main\natural_langage.py", line 569, in runNLU
    tempIntent = self.GetIntent(myInput,sujet,verbe)
  File "C:\Users\celia\PIAChatbot\app\main\natural_langage.py", line 419, in GetIntent
    listeProfession = self.getJobList()
  File "C:\Users\celia\PIAChatbot\app\main\natural_langage.py", line 202, in getJobList
    self.cursor.execute("SELECT met_metier FROM Metiers;")
  File "c:\users\celia\microblog\venv\lib\site-packages\mysql\connector\cursor_cext.py", line 233, in execute
    raise errors.ProgrammingError("Cursor is not connected")
mysql.connector.errors.ProgrammingError: Cursor is not connected
2019-05-17 21:25:17,989 INFO: PIA Chatbot startup [in C:\Users\celia\PIAChatbot\app\__init__.py:73]
2019-05-17 21:26:31,552 ERROR: Exception on /getchatbot [GET] [in c:\users\celia\microblog\venv\lib\site-packages\flask\app.py:1761]
Traceback (most recent call last):
  File "c:\users\celia\microblog\venv\lib\site-packages\flask\app.py", line 2292, in wsgi_app
    response = self.full_dispatch_request()
  File "c:\users\celia\microblog\venv\lib\site-packages\flask\app.py", line 1815, in full_dispatch_request
    rv = self.handle_user_exception(e)
  File "c:\users\celia\microblog\venv\lib\site-packages\flask\app.py", line 1718, in handle_user_exception
    reraise(exc_type, exc_value, tb)
  File "c:\users\celia\microblog\venv\lib\site-packages\flask\_compat.py", line 35, in reraise
    raise value
  File "c:\users\celia\microblog\venv\lib\site-packages\flask\app.py", line 1813, in full_dispatch_request
    rv = self.dispatch_request()
  File "c:\users\celia\microblog\venv\lib\site-packages\flask\app.py", line 1799, in dispatch_request
    return self.view_functions[rule.endpoint](**req.view_args)
  File "C:\Users\celia\PIAChatbot\app\main\routes.py", line 203, in get_bot_response
    Random_Question(cursor,userID).createQuestion()
  File "C:\Users\celia\PIAChatbot\app\main\randomQuestion.py", line 41, in createQuestion
    if(self.countConv()<=200):
  File "C:\Users\celia\PIAChatbot\app\main\randomQuestion.py", line 26, in countConv
    self.cursor.callproc('sp_countConv',args)
  File "c:\users\celia\microblog\venv\lib\site-packages\mysql\connector\cursor_cext.py", line 431, in callproc
    self.execute("SET {0}=%s".format(argname), (arg,))
  File "c:\users\celia\microblog\venv\lib\site-packages\mysql\connector\cursor_cext.py", line 233, in execute
    raise errors.ProgrammingError("Cursor is not connected")
mysql.connector.errors.ProgrammingError: Cursor is not connected
2019-05-17 21:29:38,604 INFO: PIA Chatbot startup [in C:\Users\celia\PIAChatbot\app\__init__.py:73]
2019-05-17 22:01:53,262 INFO: PIA Chatbot startup [in C:\Users\celia\PIAChatbot\app\__init__.py:73]
2019-05-17 22:02:37,836 ERROR: Exception on /getchatbot [GET] [in c:\users\celia\microblog\venv\lib\site-packages\flask\app.py:1761]
Traceback (most recent call last):
  File "c:\users\celia\microblog\venv\lib\site-packages\flask\app.py", line 2292, in wsgi_app
    response = self.full_dispatch_request()
  File "c:\users\celia\microblog\venv\lib\site-packages\flask\app.py", line 1815, in full_dispatch_request
    rv = self.handle_user_exception(e)
  File "c:\users\celia\microblog\venv\lib\site-packages\flask\app.py", line 1718, in handle_user_exception
    reraise(exc_type, exc_value, tb)
  File "c:\users\celia\microblog\venv\lib\site-packages\flask\_compat.py", line 35, in reraise
    raise value
  File "c:\users\celia\microblog\venv\lib\site-packages\flask\app.py", line 1813, in full_dispatch_request
    rv = self.dispatch_request()
  File "c:\users\celia\microblog\venv\lib\site-packages\flask\app.py", line 1799, in dispatch_request
    return self.view_functions[rule.endpoint](**req.view_args)
  File "C:\Users\celia\PIAChatbot\app\main\routes.py", line 202, in get_bot_response
    NLU(cnx,cursor,userID,str(userText)).runNLU()
  File "C:\Users\celia\PIAChatbot\app\main\natural_langage.py", line 726, in runNLU
    tempIntent = self.GetIntent(myInput,sujet,verbe)
  File "C:\Users\celia\PIAChatbot\app\main\natural_langage.py", line 391, in GetIntent
    now = datetime.datetime.now()
NameError: name 'datetime' is not defined
2019-05-17 22:04:09,899 INFO: PIA Chatbot startup [in C:\Users\celia\PIAChatbot\app\__init__.py:73]
2019-05-17 22:05:30,840 ERROR: Exception on /getchatbot [GET] [in c:\users\celia\microblog\venv\lib\site-packages\flask\app.py:1761]
Traceback (most recent call last):
  File "c:\users\celia\microblog\venv\lib\site-packages\flask\app.py", line 2292, in wsgi_app
    response = self.full_dispatch_request()
  File "c:\users\celia\microblog\venv\lib\site-packages\flask\app.py", line 1815, in full_dispatch_request
    rv = self.handle_user_exception(e)
  File "c:\users\celia\microblog\venv\lib\site-packages\flask\app.py", line 1718, in handle_user_exception
    reraise(exc_type, exc_value, tb)
  File "c:\users\celia\microblog\venv\lib\site-packages\flask\_compat.py", line 35, in reraise
    raise value
  File "c:\users\celia\microblog\venv\lib\site-packages\flask\app.py", line 1813, in full_dispatch_request
    rv = self.dispatch_request()
  File "c:\users\celia\microblog\venv\lib\site-packages\flask\app.py", line 1799, in dispatch_request
    return self.view_functions[rule.endpoint](**req.view_args)
  File "C:\Users\celia\PIAChatbot\app\main\routes.py", line 202, in get_bot_response
    NLU(cnx,cursor,userID,str(userText)).runNLU()
  File "C:\Users\celia\PIAChatbot\app\main\natural_langage.py", line 726, in runNLU
    tempIntent = self.GetIntent(myInput,sujet,verbe)
  File "C:\Users\celia\PIAChatbot\app\main\natural_langage.py", line 559, in GetIntent
    listeProfession = getJobList()
NameError: name 'getJobList' is not defined
2019-05-17 22:07:28,389 INFO: PIA Chatbot startup [in C:\Users\celia\PIAChatbot\app\__init__.py:73]
2019-05-17 22:23:08,069 INFO: PIA Chatbot startup [in C:\Users\celia\PIAChatbot\app\__init__.py:73]
2019-05-17 22:25:55,918 INFO: PIA Chatbot startup [in C:\Users\celia\PIAChatbot\app\__init__.py:73]
2019-05-17 22:31:09,339 INFO: PIA Chatbot startup [in C:\Users\celia\PIAChatbot\app\__init__.py:73]
