2019-05-17 20:08:00,261 ERROR: Exception on /historique [GET] [in c:\users\celia\microblog\venv\lib\site-packages\flask\app.py:1761]
Traceback (most recent call last):
  File "c:\users\celia\microblog\venv\lib\site-packages\sqlalchemy\engine\base.py", line 2228, in _wrap_pool_connect
    return fn()
  File "c:\users\celia\microblog\venv\lib\site-packages\sqlalchemy\pool.py", line 425, in connect
    return _ConnectionFairy._checkout(self)
  File "c:\users\celia\microblog\venv\lib\site-packages\sqlalchemy\pool.py", line 822, in _checkout
    fairy = _ConnectionRecord.checkout(pool)
  File "c:\users\celia\microblog\venv\lib\site-packages\sqlalchemy\pool.py", line 559, in checkout
    rec._checkin_failed(err)
  File "c:\users\celia\microblog\venv\lib\site-packages\sqlalchemy\util\langhelpers.py", line 67, in __exit__
    compat.reraise(exc_type, exc_value, exc_tb)
  File "c:\users\celia\microblog\venv\lib\site-packages\sqlalchemy\util\compat.py", line 277, in reraise
    raise value
  File "c:\users\celia\microblog\venv\lib\site-packages\sqlalchemy\pool.py", line 556, in checkout
    dbapi_connection = rec.get_connection()
  File "c:\users\celia\microblog\venv\lib\site-packages\sqlalchemy\pool.py", line 683, in get_connection
    self.__connect()
  File "c:\users\celia\microblog\venv\lib\site-packages\sqlalchemy\pool.py", line 701, in __connect
    connection = pool._invoke_creator(self)
  File "c:\users\celia\microblog\venv\lib\site-packages\sqlalchemy\engine\strategies.py", line 114, in connect
    return dialect.connect(*cargs, **cparams)
  File "c:\users\celia\microblog\venv\lib\site-packages\sqlalchemy\engine\default.py", line 437, in connect
    return self.dbapi.connect(*cargs, **cparams)
  File "c:\users\celia\microblog\venv\lib\site-packages\MySQLdb\__init__.py", line 84, in Connect
    return Connection(*args, **kwargs)
  File "c:\users\celia\microblog\venv\lib\site-packages\MySQLdb\connections.py", line 164, in __init__
    super(Connection, self).__init__(*args, **kwargs2)
MySQLdb._exceptions.OperationalError: (2002, "Can't connect to MySQL server on '130.79.207.104' (10060)")

The above exception was the direct cause of the following exception:

Traceback (most recent call last):
  File "c:\users\celia\microblog\venv\lib\site-packages\flask\app.py", line 2292, in wsgi_app
    response = self.full_dispatch_request()
  File "c:\users\celia\microblog\venv\lib\site-packages\flask\app.py", line 1815, in full_dispatch_request
    rv = self.handle_user_exception(e)
  File "c:\users\celia\microblog\venv\lib\site-packages\flask\app.py", line 1718, in handle_user_exception
    reraise(exc_type, exc_value, tb)
  File "c:\users\celia\microblog\venv\lib\site-packages\flask\_compat.py", line 35, in reraise
    raise value
  File "c:\users\celia\microblog\venv\lib\site-packages\flask\app.py", line 1811, in full_dispatch_request
    rv = self.preprocess_request()
  File "c:\users\celia\microblog\venv\lib\site-packages\flask\app.py", line 2087, in preprocess_request
    rv = func()
  File "C:\Users\celia\PIAChatbot\app\main\routes.py", line 22, in before_request
    if current_user.is_authenticated:
  File "c:\users\celia\microblog\venv\lib\site-packages\werkzeug\local.py", line 347, in __getattr__
    return getattr(self._get_current_object(), name)
  File "c:\users\celia\microblog\venv\lib\site-packages\werkzeug\local.py", line 306, in _get_current_object
    return self.__local()
  File "c:\users\celia\microblog\venv\lib\site-packages\flask_login\utils.py", line 26, in <lambda>
    current_user = LocalProxy(lambda: _get_user())
  File "c:\users\celia\microblog\venv\lib\site-packages\flask_login\utils.py", line 335, in _get_user
    current_app.login_manager._load_user()
  File "c:\users\celia\microblog\venv\lib\site-packages\flask_login\login_manager.py", line 359, in _load_user
    return self.reload_user()
  File "c:\users\celia\microblog\venv\lib\site-packages\flask_login\login_manager.py", line 321, in reload_user
    user = self.user_callback(user_id)
  File "C:\Users\celia\PIAChatbot\app\models.py", line 84, in load_user
    return User.query.get(int(id))
  File "c:\users\celia\microblog\venv\lib\site-packages\sqlalchemy\orm\query.py", line 936, in get
    return self._get_impl(ident, loading.load_on_pk_identity)
  File "c:\users\celia\microblog\venv\lib\site-packages\sqlalchemy\orm\query.py", line 1026, in _get_impl
    return db_load_fn(self, primary_key_identity)
  File "c:\users\celia\microblog\venv\lib\site-packages\sqlalchemy\orm\loading.py", line 282, in load_on_pk_identity
    return q.one()
  File "c:\users\celia\microblog\venv\lib\site-packages\sqlalchemy\orm\query.py", line 3039, in one
    ret = self.one_or_none()
  File "c:\users\celia\microblog\venv\lib\site-packages\sqlalchemy\orm\query.py", line 3008, in one_or_none
    ret = list(self)
  File "c:\users\celia\microblog\venv\lib\site-packages\sqlalchemy\orm\query.py", line 3081, in __iter__
    return self._execute_and_instances(context)
  File "c:\users\celia\microblog\venv\lib\site-packages\sqlalchemy\orm\query.py", line 3103, in _execute_and_instances
    querycontext, self._connection_from_session, close_with_result=True
  File "c:\users\celia\microblog\venv\lib\site-packages\sqlalchemy\orm\query.py", line 3111, in _get_bind_args
    mapper=self._bind_mapper(), clause=querycontext.statement, **kw
  File "c:\users\celia\microblog\venv\lib\site-packages\sqlalchemy\orm\query.py", line 3096, in _connection_from_session
    conn = self.session.connection(**kw)
  File "c:\users\celia\microblog\venv\lib\site-packages\sqlalchemy\orm\session.py", line 1120, in connection
    execution_options=execution_options,
  File "c:\users\celia\microblog\venv\lib\site-packages\sqlalchemy\orm\session.py", line 1126, in _connection_for_bind
    engine, execution_options
  File "c:\users\celia\microblog\venv\lib\site-packages\sqlalchemy\orm\session.py", line 424, in _connection_for_bind
    conn = bind.contextual_connect()
  File "c:\users\celia\microblog\venv\lib\site-packages\sqlalchemy\engine\base.py", line 2192, in contextual_connect
    self._wrap_pool_connect(self.pool.connect, None),
  File "c:\users\celia\microblog\venv\lib\site-packages\sqlalchemy\engine\base.py", line 2232, in _wrap_pool_connect
    e, dialect, self
  File "c:\users\celia\microblog\venv\lib\site-packages\sqlalchemy\engine\base.py", line 1528, in _handle_dbapi_exception_noconnection
    util.raise_from_cause(sqlalchemy_exception, exc_info)
  File "c:\users\celia\microblog\venv\lib\site-packages\sqlalchemy\util\compat.py", line 296, in raise_from_cause
    reraise(type(exception), exception, tb=exc_tb, cause=cause)
  File "c:\users\celia\microblog\venv\lib\site-packages\sqlalchemy\util\compat.py", line 276, in reraise
    raise value.with_traceback(tb)
  File "c:\users\celia\microblog\venv\lib\site-packages\sqlalchemy\engine\base.py", line 2228, in _wrap_pool_connect
    return fn()
  File "c:\users\celia\microblog\venv\lib\site-packages\sqlalchemy\pool.py", line 425, in connect
    return _ConnectionFairy._checkout(self)
  File "c:\users\celia\microblog\venv\lib\site-packages\sqlalchemy\pool.py", line 822, in _checkout
    fairy = _ConnectionRecord.checkout(pool)
  File "c:\users\celia\microblog\venv\lib\site-packages\sqlalchemy\pool.py", line 559, in checkout
    rec._checkin_failed(err)
  File "c:\users\celia\microblog\venv\lib\site-packages\sqlalchemy\util\langhelpers.py", line 67, in __exit__
    compat.reraise(exc_type, exc_value, exc_tb)
  File "c:\users\celia\microblog\venv\lib\site-packages\sqlalchemy\util\compat.py", line 277, in reraise
    raise value
  File "c:\users\celia\microblog\venv\lib\site-packages\sqlalchemy\pool.py", line 556, in checkout
    dbapi_connection = rec.get_connection()
  File "c:\users\celia\microblog\venv\lib\site-packages\sqlalchemy\pool.py", line 683, in get_connection
    self.__connect()
  File "c:\users\celia\microblog\venv\lib\site-packages\sqlalchemy\pool.py", line 701, in __connect
    connection = pool._invoke_creator(self)
  File "c:\users\celia\microblog\venv\lib\site-packages\sqlalchemy\engine\strategies.py", line 114, in connect
    return dialect.connect(*cargs, **cparams)
  File "c:\users\celia\microblog\venv\lib\site-packages\sqlalchemy\engine\default.py", line 437, in connect
    return self.dbapi.connect(*cargs, **cparams)
  File "c:\users\celia\microblog\venv\lib\site-packages\MySQLdb\__init__.py", line 84, in Connect
    return Connection(*args, **kwargs)
  File "c:\users\celia\microblog\venv\lib\site-packages\MySQLdb\connections.py", line 164, in __init__
    super(Connection, self).__init__(*args, **kwargs2)
sqlalchemy.exc.OperationalError: (MySQLdb._exceptions.OperationalError) (2002, "Can't connect to MySQL server on '130.79.207.104' (10060)") (Background on this error at: http://sqlalche.me/e/e3q8)
