2019-05-17 13:41:29,005 INFO: PIA Chatbot startup [in C:\Users\celia\PIAChatbot\app\__init__.py:73]
2019-05-17 13:44:26,479 INFO: PIA Chatbot startup [in C:\Users\celia\PIAChatbot\app\__init__.py:73]
2019-05-17 14:01:00,678 INFO: PIA Chatbot startup [in C:\Users\celia\PIAChatbot\app\__init__.py:73]
2019-05-17 14:07:01,196 INFO: PIA Chatbot startup [in C:\Users\celia\PIAChatbot\app\__init__.py:73]
2019-05-17 14:18:32,860 INFO: PIA Chatbot startup [in C:\Users\celia\PIAChatbot\app\__init__.py:73]
2019-05-17 14:19:59,181 INFO: PIA Chatbot startup [in C:\Users\celia\PIAChatbot\app\__init__.py:73]
2019-05-17 14:41:03,109 INFO: PIA Chatbot startup [in C:\Users\celia\PIAChatbot\app\__init__.py:73]
2019-05-17 14:45:50,962 INFO: PIA Chatbot startup [in C:\Users\celia\PIAChatbot\app\__init__.py:73]
2019-05-17 15:25:45,981 INFO: PIA Chatbot startup [in C:\Users\celia\PIAChatbot\app\__init__.py:73]
2019-05-17 16:32:41,959 INFO: PIA Chatbot startup [in C:\Users\celia\PIAChatbot\app\__init__.py:73]
2019-05-17 16:32:54,687 ERROR: Exception on /getchatbot [GET] [in c:\users\celia\microblog\venv\lib\site-packages\flask\app.py:1761]
Traceback (most recent call last):
  File "c:\users\celia\microblog\venv\lib\site-packages\flask\app.py", line 2292, in wsgi_app
    response = self.full_dispatch_request()
  File "c:\users\celia\microblog\venv\lib\site-packages\flask\app.py", line 1815, in full_dispatch_request
    rv = self.handle_user_exception(e)
  File "c:\users\celia\microblog\venv\lib\site-packages\flask\app.py", line 1718, in handle_user_exception
    reraise(exc_type, exc_value, tb)
  File "c:\users\celia\microblog\venv\lib\site-packages\flask\_compat.py", line 35, in reraise
    raise value
  File "c:\users\celia\microblog\venv\lib\site-packages\flask\app.py", line 1813, in full_dispatch_request
    rv = self.dispatch_request()
  File "c:\users\celia\microblog\venv\lib\site-packages\flask\app.py", line 1799, in dispatch_request
    return self.view_functions[rule.endpoint](**req.view_args)
  File "C:\Users\celia\PIAChatbot\app\main\routes.py", line 186, in get_bot_response
    config=ConnectionBase().config()
TypeError: config() takes 0 positional arguments but 1 was given
2019-05-17 16:34:09,897 INFO: PIA Chatbot startup [in C:\Users\celia\PIAChatbot\app\__init__.py:73]
2019-05-17 16:34:18,736 ERROR: Exception on /getchatbot [GET] [in c:\users\celia\microblog\venv\lib\site-packages\flask\app.py:1761]
Traceback (most recent call last):
  File "c:\users\celia\microblog\venv\lib\site-packages\flask\app.py", line 2292, in wsgi_app
    response = self.full_dispatch_request()
  File "c:\users\celia\microblog\venv\lib\site-packages\flask\app.py", line 1815, in full_dispatch_request
    rv = self.handle_user_exception(e)
  File "c:\users\celia\microblog\venv\lib\site-packages\flask\app.py", line 1718, in handle_user_exception
    reraise(exc_type, exc_value, tb)
  File "c:\users\celia\microblog\venv\lib\site-packages\flask\_compat.py", line 35, in reraise
    raise value
  File "c:\users\celia\microblog\venv\lib\site-packages\flask\app.py", line 1813, in full_dispatch_request
    rv = self.dispatch_request()
  File "c:\users\celia\microblog\venv\lib\site-packages\flask\app.py", line 1799, in dispatch_request
    return self.view_functions[rule.endpoint](**req.view_args)
  File "C:\Users\celia\PIAChatbot\app\main\routes.py", line 186, in get_bot_response
    config=ConnectionBase().config()
TypeError: config() takes 0 positional arguments but 1 was given
2019-05-17 16:36:51,435 INFO: PIA Chatbot startup [in C:\Users\celia\PIAChatbot\app\__init__.py:73]
2019-05-17 16:37:05,945 ERROR: Exception on /getchatbot [GET] [in c:\users\celia\microblog\venv\lib\site-packages\flask\app.py:1761]
Traceback (most recent call last):
  File "c:\users\celia\microblog\venv\lib\site-packages\flask\app.py", line 2292, in wsgi_app
    response = self.full_dispatch_request()
  File "c:\users\celia\microblog\venv\lib\site-packages\flask\app.py", line 1815, in full_dispatch_request
    rv = self.handle_user_exception(e)
  File "c:\users\celia\microblog\venv\lib\site-packages\flask\app.py", line 1718, in handle_user_exception
    reraise(exc_type, exc_value, tb)
  File "c:\users\celia\microblog\venv\lib\site-packages\flask\_compat.py", line 35, in reraise
    raise value
  File "c:\users\celia\microblog\venv\lib\site-packages\flask\app.py", line 1813, in full_dispatch_request
    rv = self.dispatch_request()
  File "c:\users\celia\microblog\venv\lib\site-packages\flask\app.py", line 1799, in dispatch_request
    return self.view_functions[rule.endpoint](**req.view_args)
  File "C:\Users\celia\PIAChatbot\app\main\routes.py", line 186, in get_bot_response
    cursor=ConnectionBase().config()
TypeError: __init__() takes 0 positional arguments but 1 was given
2019-05-17 16:37:44,386 INFO: PIA Chatbot startup [in C:\Users\celia\PIAChatbot\app\__init__.py:73]
2019-05-17 16:38:06,957 ERROR: Exception on /getchatbot [GET] [in c:\users\celia\microblog\venv\lib\site-packages\flask\app.py:1761]
Traceback (most recent call last):
  File "c:\users\celia\microblog\venv\lib\site-packages\flask\app.py", line 2292, in wsgi_app
    response = self.full_dispatch_request()
  File "c:\users\celia\microblog\venv\lib\site-packages\flask\app.py", line 1815, in full_dispatch_request
    rv = self.handle_user_exception(e)
  File "c:\users\celia\microblog\venv\lib\site-packages\flask\app.py", line 1718, in handle_user_exception
    reraise(exc_type, exc_value, tb)
  File "c:\users\celia\microblog\venv\lib\site-packages\flask\_compat.py", line 35, in reraise
    raise value
  File "c:\users\celia\microblog\venv\lib\site-packages\flask\app.py", line 1813, in full_dispatch_request
    rv = self.dispatch_request()
  File "c:\users\celia\microblog\venv\lib\site-packages\flask\app.py", line 1799, in dispatch_request
    return self.view_functions[rule.endpoint](**req.view_args)
  File "C:\Users\celia\PIAChatbot\app\main\routes.py", line 186, in get_bot_response
    cursor=ConnectionBase().config()
TypeError: 'dict' object is not callable
2019-05-17 16:39:51,258 INFO: PIA Chatbot startup [in C:\Users\celia\PIAChatbot\app\__init__.py:73]
2019-05-17 16:39:59,511 ERROR: Exception on /getchatbot [GET] [in c:\users\celia\microblog\venv\lib\site-packages\flask\app.py:1761]
Traceback (most recent call last):
  File "c:\users\celia\microblog\venv\lib\site-packages\flask\app.py", line 2292, in wsgi_app
    response = self.full_dispatch_request()
  File "c:\users\celia\microblog\venv\lib\site-packages\flask\app.py", line 1815, in full_dispatch_request
    rv = self.handle_user_exception(e)
  File "c:\users\celia\microblog\venv\lib\site-packages\flask\app.py", line 1718, in handle_user_exception
    reraise(exc_type, exc_value, tb)
  File "c:\users\celia\microblog\venv\lib\site-packages\flask\_compat.py", line 35, in reraise
    raise value
  File "c:\users\celia\microblog\venv\lib\site-packages\flask\app.py", line 1813, in full_dispatch_request
    rv = self.dispatch_request()
  File "c:\users\celia\microblog\venv\lib\site-packages\flask\app.py", line 1799, in dispatch_request
    return self.view_functions[rule.endpoint](**req.view_args)
  File "C:\Users\celia\PIAChatbot\app\main\routes.py", line 186, in get_bot_response
    cursor=ConnectionBase().config()
TypeError: 'dict' object is not callable
2019-05-17 16:41:14,368 INFO: PIA Chatbot startup [in C:\Users\celia\PIAChatbot\app\__init__.py:73]
2019-05-17 16:41:30,555 ERROR: Exception on /getchatbot [GET] [in c:\users\celia\microblog\venv\lib\site-packages\flask\app.py:1761]
Traceback (most recent call last):
  File "c:\users\celia\microblog\venv\lib\site-packages\flask\app.py", line 2292, in wsgi_app
    response = self.full_dispatch_request()
  File "c:\users\celia\microblog\venv\lib\site-packages\flask\app.py", line 1815, in full_dispatch_request
    rv = self.handle_user_exception(e)
  File "c:\users\celia\microblog\venv\lib\site-packages\flask\app.py", line 1718, in handle_user_exception
    reraise(exc_type, exc_value, tb)
  File "c:\users\celia\microblog\venv\lib\site-packages\flask\_compat.py", line 35, in reraise
    raise value
  File "c:\users\celia\microblog\venv\lib\site-packages\flask\app.py", line 1813, in full_dispatch_request
    rv = self.dispatch_request()
  File "c:\users\celia\microblog\venv\lib\site-packages\flask\app.py", line 1799, in dispatch_request
    return self.view_functions[rule.endpoint](**req.view_args)
  File "C:\Users\celia\PIAChatbot\app\main\routes.py", line 186, in get_bot_response
    cursor=ConnectionBase().config()
TypeError: 'dict' object is not callable
2019-05-17 16:42:27,302 INFO: PIA Chatbot startup [in C:\Users\celia\PIAChatbot\app\__init__.py:73]
2019-05-17 16:42:36,734 ERROR: Exception on /getchatbot [GET] [in c:\users\celia\microblog\venv\lib\site-packages\flask\app.py:1761]
Traceback (most recent call last):
  File "c:\users\celia\microblog\venv\lib\site-packages\flask\app.py", line 2292, in wsgi_app
    response = self.full_dispatch_request()
  File "c:\users\celia\microblog\venv\lib\site-packages\flask\app.py", line 1815, in full_dispatch_request
    rv = self.handle_user_exception(e)
  File "c:\users\celia\microblog\venv\lib\site-packages\flask\app.py", line 1718, in handle_user_exception
    reraise(exc_type, exc_value, tb)
  File "c:\users\celia\microblog\venv\lib\site-packages\flask\_compat.py", line 35, in reraise
    raise value
  File "c:\users\celia\microblog\venv\lib\site-packages\flask\app.py", line 1813, in full_dispatch_request
    rv = self.dispatch_request()
  File "c:\users\celia\microblog\venv\lib\site-packages\flask\app.py", line 1799, in dispatch_request
    return self.view_functions[rule.endpoint](**req.view_args)
  File "C:\Users\celia\PIAChatbot\app\main\routes.py", line 187, in get_bot_response
    cursor=ConnectionBase().config()
TypeError: 'dict' object is not callable
2019-05-17 16:50:52,427 INFO: PIA Chatbot startup [in C:\Users\celia\PIAChatbot\app\__init__.py:73]
